Workbook

Sheet Materia prima
A1: BENEFICIO | B1: 0.35
A3: MATERIALES
A4: CODIGO | B4: ITEM | C4: COSTO UNIT. | D4: UNIDAD | E4: COSTO PROD. | F4: PRECIO
A5: M1 | B5: Cera alto pf | C5: =3905*2/1000 -> 7.81 | D5: gr | E5: =C5 -> 7.81 | F5: =E5*(1+'Materia prima'!$B$1) -> 10.5435
A6: M2 | B6: Cera bajo pf | C6: =7500/1000 -> 7.5 | E6: =C6 -> 7.5 | F6: =E6*(1+'Materia prima'!$B$1) -> 10.125
A7: M3 | B7: Colorante | C7: =1700/10 -> 170 | D7: ml | E7: =C7 -> 170 | F7: =E7*(1+'Materia prima'!$B$1) -> 229.5
A8: M4 | B8: Escencia | C8: =6000*1.25/50 -> 150 | D8: ml | E8: =C8 -> 150 | F8: =E8*(1+'Materia prima'!$B$1) -> 202.5
A9: M5 | B9: Pabilo | C9: =1000/10 -> 100 | D9: unid. | E9: =C9 -> 100 | F9: =E9*(1+'Materia prima'!$B$1) -> 135
A10: M6 | B10: Aceite de Coco | C10: 18000 | D10: unid. | E10: =C10 -> 18000 | F10: =E10*(1+'Materia prima'!$B$1) -> 24300
A11: M7 | B11: Yeso | C11: =18000*3/40 -> 1350 | D11: kg | E11: =C11 -> 1350 | F11: =E11*(1+'Materia prima'!$B$1) -> 1822.5
A12: M8 | B12: Barniz al agua | C12: =CEILING(3200/15,5) -> 215 | D12: ml | E12: =C12 -> 215 | F12: =E12*(1+'Materia prima'!$B$1) -> 290.25
F13: =E13*(1+'Materia prima'!$B$1) -> 0
F14: =E14*(1+'Materia prima'!$B$1) -> 0
F15: =E15*(1+'Materia prima'!$B$1) -> 0
F16: =E16*(1+'Materia prima'!$B$1) -> 0
A24: ACCESORIOS
A25: A1 | B25: Flores decoracion | C25: 200 | D25: unid. | E25: =C25 -> 200 | F25: =E25*(1+'Materia prima'!$B$1) -> 270
A26: A2 | B26: Tarjeta decoracion | C26: =CEILING(450*3/3.5*1.28,10) -> 500 | D26: unid. | E26: =C26 -> 500 | F26: =E26*(1+'Materia prima'!$B$1) -> 675
A27: A3 | B27: Cinta | C27: =765/5*0.3 -> 45.9 | D27: unid. | E27: =C27 -> 45.9 | F27: =E27*(1+'Materia prima'!$B$1) -> 61.965
A28: A4 | B28: Tarjeta presentacion | C28: 150 | D28: unid. | E28: =C28 -> 150 | F28: =E28*(1+'Materia prima'!$B$1) -> 202.5
A29: A5 | B29: Dije Cruz Dorada | C29: =6500/68 -> 95.588235 | D29: unid. | E29: =C29 -> 95.588235 | F29: =E29*(1+'Materia prima'!$B$1) -> 129.04412
A31: EMPAQUE
A32: E1 | B32: Bolsa organza 25x30 | C32: =CEILING(23000/25,10) -> 920 | D32: unid. | E32: =C32 -> 920 | F32: =E32*(1+'Materia prima'!$B$1) -> 1242
A33: E2 | B33: Bolsa organza 15x20 | C33: =CEILING(13000/25,10) -> 520 | D33: unid. | E33: =C33 -> 520 | F33: =E33*(1+'Materia prima'!$B$1) -> 702
A34: E3 | B34: Caja con visor corazon | C34: 500 | D34: unid. | E34: =C34 -> 500 | F34: =E34*(1+'Materia prima'!$B$1) -> 675
A35: E4 | B35: Bolsa celofan 10x20 | C35: =1200/10*1.5 -> 180 | D35: unid. | E35: =C35 -> 180 | F35: =E35*(1+'Materia prima'!$B$1) -> 243
A36: E5 | B36: Tul | C36: =CEILING(30000/(10*1)*(0.5*0.6),10) -> 900 | D36: unid. | E36: =C36 -> 900 | F36: =E36*(1+'Materia prima'!$B$1) -> 1215
A37: E6 | B37: Caja exagonal | D37: unid. | E37: 2000 | F37: =E37*(1+'Materia prima'!$B$1) -> 2700
A38: E7 | B38: Bolsa gruesa | C38: =7300/24 -> 304.16667 | D38: unid. | E38: 1500 | F38: =E38*(1+'Materia prima'!$B$1) -> 2025
A39: E8 | B39: Bolsa plastico 15X20 | C39: =CEILING(20000/50,10) -> 400 | D39: unid. | E39: =C39 -> 400 | F39: =E39*(1+'Materia prima'!$B$1) -> 540
A40: E9 | B40: Mini Cajas | C40: =CEILING(49000/60,10) -> 820 | D40: unid. | E40: =C40 -> 820 | F40: =E40*(1+'Materia prima'!$B$1) -> 1107
A41: E10 | B41: Bolsa organza 9x12 | C41: 250 | D41: unid. | E41: =C41 -> 250 | F41: =E41*(1+'Materia prima'!$B$1) -> 337.5
A42: E11 | B42: Bolsa organza 9x12 comunion | C42: =9000/20 -> 450 | D42: unid. | E42: =C42 -> 450 | F42: =E42*(1+'Materia prima'!$B$1) -> 607.5
A43: E12 | B43: Bolsa organza 17x23 | C43: =CEILING(13000/25,10) -> 520 | D43: unid. | E43: =C43 -> 520 | F43: =E43*(1+'Materia prima'!$B$1) -> 702
A50: MANO DE OBRA
A51: MO | B51: Mano de obra | C51: 7000 | D51: hs | E51: =C51 -> 7000 | F51: =E51*(1+'Materia prima'!$B$1) -> 9450

Sheet Costos
N1: 7 | O1: =10/300/20 -> 0.0016666667 | P1: =0.01/50 -> 0.0002
A2: CODIGO | B2: ITEM | C2: COSTO UNIT. | D2: UNIDAD | E2: COSTO PROD. | F2: PRECIO | H2: Cera alto pf | I2: Cera bajo pf | J2: Pabilo | K2: Recipiente | L2: Yeso | M2: Mano de obra | N2: Escencia | O2: Colorante | P2: Aceite de Coco | R2: Cera alto pf | S2: Cera bajo pf | T2: Pabilo | U2: Recipiente | V2: Yeso | W2: Escencia | X2: Colorante | Y2: Aceite de Coco | Z2: Mano de obra | AA2: Materiales | AB2: Subtotal | AC2: 1.07 | AF2: MO/Subtotal | AG2: Precio/Mat | AH2: Precio/Subtotal | AI2: Beneficio | AJ2: Beneficio/Precio
A3: VELAS | O3: =IF((H3+I3)>0,O$1*(H3+I3),0) -> 0
A4: V1 | B4: Pino chico | E4: =AC4 -> 7700 | F4: =+E4*(1+'Materia prima'!$B$1) -> 10395 | H4: 82 | I4: 0 | J4: 0.5 | K4: 0 | L4: 0 | M4: 45 | N4: =IF((H4+I4)>0,N$1/100*(H4+I4),0) -> 5.74 | O4: =IF((H4+I4)>0,O$1*(H4+I4),0) -> 0.13666667 | P4: =IF((H4+I4)>0,P$1*(H4+I4),0) -> 0.0164 | R4: =VLOOKUP(R$2,'Materia prima'!$B:$J,2,0)*H4 -> 640.42 | S4: =VLOOKUP(S$2,'Materia prima'!$B:$J,2,0)*I4 -> 0 | T4: =VLOOKUP(T$2,'Materia prima'!$B:$J,2,0)*J4 -> 50 | U4: =C4*K4 -> 0 | V4: =VLOOKUP(V$2,'Materia prima'!$B:$J,2,0)*L4/1000 -> 0 | W4: =VLOOKUP(W$2,'Materia prima'!$B:$J,2,0)*N4 -> 861 | X4: =VLOOKUP(X$2,'Materia prima'!$B:$J,2,0)*O4 -> 23.233333 | Y4: =VLOOKUP(Y$2,'Materia prima'!$B:$J,2,0)*P4 -> 295.2 | Z4: =VLOOKUP(Z$2,'Materia prima'!$B:$J,2,0)*M4/60 -> 5250 | AA4: =SUM(R4:Y4) -> 1869.8533 | AB4: =SUM(Z4:AA4) -> 7119.8533 | AC4: =CEILING(AB4*$AC$2,100) -> 7700 | AD4: =AC4/AB4 -> 1.081483 | AF4: =Z4/AB4 -> 0.73737474 | AG4: =$F4/AA4-1 -> 4.5592595 | AH4: =$F4/AB4-1 -> 0.46000199 | AI4: =F4-AA4 -> 8525.1467 | AJ4: =AI4/$F4 -> 0.82011993
A5: V2 | B5: Pino grande | E5: =AC5 -> 12200 | F5: =+E5*(1+'Materia prima'!$B$1) -> 16470 | H5: 179 | I5: 0 | J5: 0.75 | K5: 0 | L5: 0 | M5: 63 | N5: =IF((H5+I5)>0,N$1/100*(H5+I5),0) -> 12.53 | O5: =IF((H5+I5)>0,O$1*(H5+I5),0) -> 0.29833333 | P5: =IF((H5+I5)>0,P$1*(H5+I5),0) -> 0.0358 | R5: =VLOOKUP(R$2,'Materia prima'!$B:$J,2,0)*H5 -> 1397.99 | S5: =VLOOKUP(S$2,'Materia prima'!$B:$J,2,0)*I5 -> 0 | T5: =VLOOKUP(T$2,'Materia prima'!$B:$J,2,0)*J5 -> 75 | U5: =C5*K5 -> 0 | V5: =VLOOKUP(V$2,'Materia prima'!$B:$J,2,0)*L5/1000 -> 0 | W5: =VLOOKUP(W$2,'Materia prima'!$B:$J,2,0)*N5 -> 1879.5 | X5: =VLOOKUP(X$2,'Materia prima'!$B:$J,2,0)*O5 -> 50.716667 | Y5: =VLOOKUP(Y$2,'Materia prima'!$B:$J,2,0)*P5 -> 644.4 | Z5: =VLOOKUP(Z$2,'Materia prima'!$B:$J,2,0)*M5/60 -> 7350 | AA5: =SUM(R5:Y5) -> 4047.6067 | AB5: =SUM(Z5:AA5) -> 11397.607 | AC5: =CEILING(AB5*$AC$2,100) -> 12200 | AD5: =AC5/AB5 -> 1.0704002 | AF5: =Z5/AB5 -> 0.64487223 | AG5: =$F5/AA5-1 -> 3.0690713 | AH5: =$F5/AB5-1 -> 0.44504022 | AI5: =F5-AA5 -> 12422.393 | AJ5: =AI5/$F5 -> 0.75424368
A6: V3 | B6: Margaritas | E6: =AC6 -> 3000 | F6: =+E6*(1+'Materia prima'!$B$1) -> 4050 | H6: 20 | I6: 0 | J6: 0.15 | K6: 0 | L6: 0 | M6: 20 | N6: =IF((H6+I6)>0,N$1/100*(H6+I6),0) -> 1.4 | O6: =IF((H6+I6)>0,O$1*(H6+I6),0) -> 0.033333333 | P6: =IF((H6+I6)>0,P$1*(H6+I6),0) -> 0.004 | R6: =VLOOKUP(R$2,'Materia prima'!$B:$J,2,0)*H6 -> 156.2 | S6: =VLOOKUP(S$2,'Materia prima'!$B:$J,2,0)*I6 -> 0 | T6: =VLOOKUP(T$2,'Materia prima'!$B:$J,2,0)*J6 -> 15 | U6: =C6*K6 -> 0 | V6: =VLOOKUP(V$2,'Materia prima'!$B:$J,2,0)*L6/1000 -> 0 | W6: =VLOOKUP(W$2,'Materia prima'!$B:$J,2,0)*N6 -> 210 | X6: =VLOOKUP(X$2,'Materia prima'!$B:$J,2,0)*O6 -> 5.6666667 | Y6: =VLOOKUP(Y$2,'Materia prima'!$B:$J,2,0)*P6 -> 72 | Z6: =VLOOKUP(Z$2,'Materia prima'!$B:$J,2,0)*M6/60 -> 2333.3333 | AA6: =SUM(R6:Y6) -> 458.86667 | AB6: =SUM(Z6:AA6) -> 2792.2 | AC6: =CEILING(AB6*$AC$2,100) -> 3000 | AD6: =AC6/AB6 -> 1.0744216 | AF6: =Z6/AB6 -> 0.83566125 | AG6: =$F6/AA6-1 -> 7.8260933 | AH6: =$F6/AB6-1 -> 0.45046916 | AI6: =F6-AA6 -> 3591.1333 | AJ6: =AI6/$F6 -> 0.88669959
A7: V4 | B7: Estrella | E7: =AC7 -> 5100 | F7: =+E7*(1+'Materia prima'!$B$1) -> 6885 | H7: 55 | I7: 0 | J7: 0.2 | K7: 0 | L7: 0 | M7: 30 | N7: =IF((H7+I7)>0,N$1/100*(H7+I7),0) -> 3.85 | O7: =IF((H7+I7)>0,O$1*(H7+I7),0) -> 0.091666667 | P7: =IF((H7+I7)>0,P$1*(H7+I7),0) -> 0.011 | R7: =VLOOKUP(R$2,'Materia prima'!$B:$J,2,0)*H7 -> 429.55 | S7: =VLOOKUP(S$2,'Materia prima'!$B:$J,2,0)*I7 -> 0 | T7: =VLOOKUP(T$2,'Materia prima'!$B:$J,2,0)*J7 -> 20 | U7: =C7*K7 -> 0 | V7: =VLOOKUP(V$2,'Materia prima'!$B:$J,2,0)*L7/1000 -> 0 | W7: =VLOOKUP(W$2,'Materia prima'!$B:$J,2,0)*N7 -> 577.5 | X7: =VLOOKUP(X$2,'Materia prima'!$B:$J,2,0)*O7 -> 15.583333 | Y7: =VLOOKUP(Y$2,'Materia prima'!$B:$J,2,0)*P7 -> 198 | Z7: =VLOOKUP(Z$2,'Materia prima'!$B:$J,2,0)*M7/60 -> 3500 | AA7: =SUM(R7:Y7) -> 1240.6333 | AB7: =SUM(Z7:AA7) -> 4740.6333 | AC7: =CEILING(AB7*$AC$2,100) -> 5100 | AD7: =AC7/AB7 -> 1.0758056 | AF7: =Z7/AB7 -> 0.73829798 | AG7: =$F7/AA7-1 -> 4.5495849 | AH7: =$F7/AB7-1 -> 0.45233759 | AI7: =F7-AA7 -> 5644.3667 | AJ7: =AI7/$F7 -> 0.81980634
A8: V5 | B8: Rosa | E8: =AC8 -> 4900 | F8: =+E8*(1+'Materia prima'!$B$1) -> 6615 | H8: 40 | I8: 0 | J8: 1 | K8: 0 | L8: 0 | M8: 30 | N8: =IF((H8+I8)>0,N$1/100*(H8+I8),0) -> 2.8 | O8: =IF((H8+I8)>0,O$1*(H8+I8),0) -> 0.066666667 | P8: =IF((H8+I8)>0,P$1*(H8+I8),0) -> 0.008 | R8: =VLOOKUP(R$2,'Materia prima'!$B:$J,2,0)*H8 -> 312.4 | S8: =VLOOKUP(S$2,'Materia prima'!$B:$J,2,0)*I8 -> 0 | T8: =VLOOKUP(T$2,'Materia prima'!$B:$J,2,0)*J8 -> 100 | U8: =C8*K8 -> 0 | V8: =VLOOKUP(V$2,'Materia prima'!$B:$J,2,0)*L8/1000 -> 0 | W8: =VLOOKUP(W$2,'Materia prima'!$B:$J,2,0)*N8 -> 420 | X8: =VLOOKUP(X$2,'Materia prima'!$B:$J,2,0)*O8 -> 11.333333 | Y8: =VLOOKUP(Y$2,'Materia prima'!$B:$J,2,0)*P8 -> 144 | Z8: =VLOOKUP(Z$2,'Materia prima'!$B:$J,2,0)*M8/60 -> 3500 | AA8: =SUM(R8:Y8) -> 987.73333 | AB8: =SUM(Z8:AA8) -> 4487.7333 | AC8: =CEILING(AB8*$AC$2,100) -> 4900 | AD8: =AC8/AB8 -> 1.0918652 | AF8: =Z8/AB8 -> 0.77990374 | AG8: =$F8/AA8-1 -> 5.6971517 | AH8: =$F8/AB8-1 -> 0.47401806 | AI8: =F8-AA8 -> 5627.2667 | AJ8: =AI8/$F8 -> 0.85068279
A9: V6 | B9: Sagrada Familia | E9: =AC9 -> 9000 | F9: =+E9*(1+'Materia prima'!$B$1) -> 12150 | H9: 136 | I9: 0 | J9: 0.5 | K9: 0 | L9: 0 | M9: 45 | N9: =IF((H9+I9)>0,N$1/100*(H9+I9),0) -> 9.52 | O9: =IF((H9+I9)>0,O$1*(H9+I9),0) -> 0.22666667 | P9: =IF((H9+I9)>0,P$1*(H9+I9),0) -> 0.0272 | R9: =VLOOKUP(R$2,'Materia prima'!$B:$J,2,0)*H9 -> 1062.16 | S9: =VLOOKUP(S$2,'Materia prima'!$B:$J,2,0)*I9 -> 0 | T9: =VLOOKUP(T$2,'Materia prima'!$B:$J,2,0)*J9 -> 50 | U9: =C9*K9 -> 0 | V9: =VLOOKUP(V$2,'Materia prima'!$B:$J,2,0)*L9/1000 -> 0 | W9: =VLOOKUP(W$2,'Materia prima'!$B:$J,2,0)*N9 -> 1428 | X9: =VLOOKUP(X$2,'Materia prima'!$B:$J,2,0)*O9 -> 38.533333 | Y9: =VLOOKUP(Y$2,'Materia prima'!$B:$J,2,0)*P9 -> 489.6 | Z9: =VLOOKUP(Z$2,'Materia prima'!$B:$J,2,0)*M9/60 -> 5250 | AA9: =SUM(R9:Y9) -> 3068.2933 | AB9: =SUM(Z9:AA9) -> 8318.2933 | AC9: =CEILING(AB9*$AC$2,100) -> 9000 | AD9: =AC9/AB9 -> 1.0819527 | AF9: =Z9/AB9 -> 0.63113908 | AG9: =$F9/AA9-1 -> 2.9598561 | AH9: =$F9/AB9-1 -> 0.46063616 | AI9: =F9-AA9 -> 9081.7067 | AJ9: =AI9/$F9 -> 0.74746557
A10: V7 | B10: Flor Loto | E10: =AC10 -> 5500 | F10: =+E10*(1+'Materia prima'!$B$1) -> 7425 | H10: 71 | I10: 0 | J10: 0.25 | K10: 0 | L10: 0 | M10: 30 | N10: =IF((H10+I10)>0,N$1/100*(H10+I10),0) -> 4.97 | O10: =IF((H10+I10)>0,O$1*(H10+I10),0) -> 0.11833333 | P10: =IF((H10+I10)>0,P$1*(H10+I10),0) -> 0.0142 | R10: =VLOOKUP(R$2,'Materia prima'!$B:$J,2,0)*H10 -> 554.51 | S10: =VLOOKUP(S$2,'Materia prima'!$B:$J,2,0)*I10 -> 0 | T10: =VLOOKUP(T$2,'Materia prima'!$B:$J,2,0)*J10 -> 25 | U10: =C10*K10 -> 0 | V10: =VLOOKUP(V$2,'Materia prima'!$B:$J,2,0)*L10/1000 -> 0 | W10: =VLOOKUP(W$2,'Materia prima'!$B:$J,2,0)*N10 -> 745.5 | X10: =VLOOKUP(X$2,'Materia prima'!$B:$J,2,0)*O10 -> 20.116667 | Y10: =VLOOKUP(Y$2,'Materia prima'!$B:$J,2,0)*P10 -> 255.6 | Z10: =VLOOKUP(Z$2,'Materia prima'!$B:$J,2,0)*M10/60 -> 3500 | AA10: =SUM(R10:Y10) -> 1600.7267 | AB10: =SUM(Z10:AA10) -> 5100.7267 | AC10: =CEILING(AB10*$AC$2,100) -> 5500 | AD10: =AC10/AB10 -> 1.0782777 | AF10: =Z10/AB10 -> 0.68617674 | AG10: =$F10/AA10-1 -> 3.6385183 | AH10: =$F10/AB10-1 -> 0.45567494 | AI10: =F10-AA10 -> 5824.2733 | AJ10: =AI10/$F10 -> 0.78441392
A11: V8 | B11: Velon Mediano | E11: =AC11 -> 12000 | F11: =+E11*(1+'Materia prima'!$B$1) -> 16200 | H11: 265 | I11: 0 | J11: 0.75 | K11: 0 | L11: 0 | M11: 45 | N11: =IF((H11+I11)>0,N$1/100*(H11+I11),0) -> 18.55 | O11: =IF((H11+I11)>0,O$1*(H11+I11),0) -> 0.44166667 | P11: =IF((H11+I11)>0,P$1*(H11+I11),0) -> 0.053 | R11: =VLOOKUP(R$2,'Materia prima'!$B:$J,2,0)*H11 -> 2069.65 | S11: =VLOOKUP(S$2,'Materia prima'!$B:$J,2,0)*I11 -> 0 | T11: =VLOOKUP(T$2,'Materia prima'!$B:$J,2,0)*J11 -> 75 | U11: =C11*K11 -> 0 | V11: =VLOOKUP(V$2,'Materia prima'!$B:$J,2,0)*L11/1000 -> 0 | W11: =VLOOKUP(W$2,'Materia prima'!$B:$J,2,0)*N11 -> 2782.5 | X11: =VLOOKUP(X$2,'Materia prima'!$B:$J,2,0)*O11 -> 75.083333 | Y11: =VLOOKUP(Y$2,'Materia prima'!$B:$J,2,0)*P11 -> 954 | Z11: =VLOOKUP(Z$2,'Materia prima'!$B:$J,2,0)*M11/60 -> 5250 | AA11: =SUM(R11:Y11) -> 5956.2333 | AB11: =SUM(Z11:AA11) -> 11206.233 | AC11: =CEILING(AB11*$AC$2,100) -> 12000 | AD11: =AC11/AB11 -> 1.0708326 | AF11: =Z11/AB11 -> 0.46848926 | AG11: =$F11/AA11-1 -> 1.7198397 | AH11: =$F11/AB11-1 -> 0.44562401 | AI11: =F11-AA11 -> 10243.767 | AJ11: =AI11/$F11 -> 0.63233128
A12: V9 | B12: Velon Pequeño | E12: =AC12 -> 8300 | F12: =+E12*(1+'Materia prima'!$B$1) -> 11205 | H12: 110 | I12: 0 | J12: 0.5 | K12: 0 | L12: 0 | M12: 45 | N12: =IF((H12+I12)>0,N$1/100*(H12+I12),0) -> 7.7 | O12: =IF((H12+I12)>0,O$1*(H12+I12),0) -> 0.18333333 | P12: =IF((H12+I12)>0,P$1*(H12+I12),0) -> 0.022 | R12: =VLOOKUP(R$2,'Materia prima'!$B:$J,2,0)*H12 -> 859.1 | S12: =VLOOKUP(S$2,'Materia prima'!$B:$J,2,0)*I12 -> 0 | T12: =VLOOKUP(T$2,'Materia prima'!$B:$J,2,0)*J12 -> 50 | U12: =C12*K12 -> 0 | V12: =VLOOKUP(V$2,'Materia prima'!$B:$J,2,0)*L12/1000 -> 0 | W12: =VLOOKUP(W$2,'Materia prima'!$B:$J,2,0)*N12 -> 1155 | X12: =VLOOKUP(X$2,'Materia prima'!$B:$J,2,0)*O12 -> 31.166667 | Y12: =VLOOKUP(Y$2,'Materia prima'!$B:$J,2,0)*P12 -> 396 | Z12: =VLOOKUP(Z$2,'Materia prima'!$B:$J,2,0)*M12/60 -> 5250 | AA12: =SUM(R12:Y12) -> 2491.2667 | AB12: =SUM(Z12:AA12) -> 7741.2667 | AC12: =CEILING(AB12*$AC$2,100) -> 8300 | AD12: =AC12/AB12 -> 1.072176 | AF12: =Z12/AB12 -> 0.67818359 | AG12: =$F12/AA12-1 -> 3.497712 | AH12: =$F12/AB12-1 -> 0.44743754 | AI12: =F12-AA12 -> 8713.7333 | AJ12: =AI12/$F12 -> 0.77766473
A13: V10 | B13: Vela Alhajero | E13: =AC13 -> 6200 | F13: =+E13*(1+'Materia prima'!$B$1) -> 8370 | H13: 0 | I13: 100 | J13: 0.15 | K13: 1 | L13: 0 | M13: 30 | N13: =IF((H13+I13)>0,N$1/100*(H13+I13),0) -> 7 | O13: =IF((H13+I13)>0,O$1*(H13+I13),0) -> 0.16666667 | P13: =IF((H13+I13)>0,P$1*(H13+I13),0) -> 0.02 | R13: =VLOOKUP(R$2,'Materia prima'!$B:$J,2,0)*H13 -> 0 | S13: =VLOOKUP(S$2,'Materia prima'!$B:$J,2,0)*I13 -> 750 | T13: =VLOOKUP(T$2,'Materia prima'!$B:$J,2,0)*J13 -> 15 | U13: =C13*K13 -> 0 | V13: =VLOOKUP(V$2,'Materia prima'!$B:$J,2,0)*L13/1000 -> 0 | W13: =VLOOKUP(W$2,'Materia prima'!$B:$J,2,0)*N13 -> 1050 | X13: =VLOOKUP(X$2,'Materia prima'!$B:$J,2,0)*O13 -> 28.333333 | Y13: =VLOOKUP(Y$2,'Materia prima'!$B:$J,2,0)*P13 -> 360 | Z13: =VLOOKUP(Z$2,'Materia prima'!$B:$J,2,0)*M13/60 -> 3500 | AA13: =SUM(R13:Y13) -> 2203.3333 | AB13: =SUM(Z13:AA13) -> 5703.3333 | AC13: =CEILING(AB13*$AC$2,100) -> 6200 | AD13: =AC13/AB13 -> 1.0870836 | AF13: =Z13/AB13 -> 0.61367621 | AG13: =$F13/AA13-1 -> 2.7987897 | AH13: =$F13/AB13-1 -> 0.46756283 | AI13: =F13-AA13 -> 6166.6667 | AJ13: =AI13/$F13 -> 0.73675826
A14: V11 | B14: Corazon Rosa | E14: =AC14 -> 4900 | F14: =+E14*(1+'Materia prima'!$B$1) -> 6615 | H14: 44 | I14: 0 | J14: 1 | K14: 0 | L14: 0 | M14: 30 | N14: =IF((H14+I14)>0,N$1/100*(H14+I14),0) -> 3.08 | O14: =IF((H14+I14)>0,O$1*(H14+I14),0) -> 0.073333333 | P14: =IF((H14+I14)>0,P$1*(H14+I14),0) -> 0.0088 | R14: =VLOOKUP(R$2,'Materia prima'!$B:$J,2,0)*H14 -> 343.64 | S14: =VLOOKUP(S$2,'Materia prima'!$B:$J,2,0)*I14 -> 0 | T14: =VLOOKUP(T$2,'Materia prima'!$B:$J,2,0)*J14 -> 100 | U14: =C14*K14 -> 0 | V14: =VLOOKUP(V$2,'Materia prima'!$B:$J,2,0)*L14/1000 -> 0 | W14: =VLOOKUP(W$2,'Materia prima'!$B:$J,2,0)*N14 -> 462 | X14: =VLOOKUP(X$2,'Materia prima'!$B:$J,2,0)*O14 -> 12.466667 | Y14: =VLOOKUP(Y$2,'Materia prima'!$B:$J,2,0)*P14 -> 158.4 | Z14: =VLOOKUP(Z$2,'Materia prima'!$B:$J,2,0)*M14/60 -> 3500 | AA14: =SUM(R14:Y14) -> 1076.5067 | AB14: =SUM(Z14:AA14) -> 4576.5067 | AC14: =CEILING(AB14*$AC$2,100) -> 4900 | AD14: =AC14/AB14 -> 1.0706856 | AF14: =Z14/AB14 -> 0.76477546 | AG14: =$F14/AA14-1 -> 5.144876 | AH14: =$F14/AB14-1 -> 0.44542562 | AI14: =F14-AA14 -> 5538.4933 | AJ14: =AI14/$F14 -> 0.83726279
A15: V12 | B15: Corazon texturizado Grande | E15: =AC15 -> 5900 | F15: =+E15*(1+'Materia prima'!$B$1) -> 7965 | H15: 84 | I15: 0 | J15: 1 | K15: 0 | L15: 0 | M15: 30 | N15: =IF((H15+I15)>0,N$1/100*(H15+I15),0) -> 5.88 | O15: =IF((H15+I15)>0,O$1*(H15+I15),0) -> 0.14 | P15: =IF((H15+I15)>0,P$1*(H15+I15),0) -> 0.0168 | R15: =VLOOKUP(R$2,'Materia prima'!$B:$J,2,0)*H15 -> 656.04 | S15: =VLOOKUP(S$2,'Materia prima'!$B:$J,2,0)*I15 -> 0 | T15: =VLOOKUP(T$2,'Materia prima'!$B:$J,2,0)*J15 -> 100 | U15: =C15*K15 -> 0 | V15: =VLOOKUP(V$2,'Materia prima'!$B:$J,2,0)*L15/1000 -> 0 | W15: =VLOOKUP(W$2,'Materia prima'!$B:$J,2,0)*N15 -> 882 | X15: =VLOOKUP(X$2,'Materia prima'!$B:$J,2,0)*O15 -> 23.8 | Y15: =VLOOKUP(Y$2,'Materia prima'!$B:$J,2,0)*P15 -> 302.4 | Z15: =VLOOKUP(Z$2,'Materia prima'!$B:$J,2,0)*M15/60 -> 3500 | AA15: =SUM(R15:Y15) -> 1964.24 | AB15: =SUM(Z15:AA15) -> 5464.24 | AC15: =CEILING(AB15*$AC$2,100) -> 5900 | AD15: =AC15/AB15 -> 1.0797476 | AF15: =Z15/AB15 -> 0.64052823 | AG15: =$F15/AA15-1 -> 3.0550035 | AH15: =$F15/AB15-1 -> 0.45765925 | AI15: =F15-AA15 -> 6000.76 | AJ15: =AI15/$F15 -> 0.75339109
... A34: V31 | B34: Arcoiris | E34: =AC34 -> 5900 | F34: =+E34*(1+'Materia prima'!$B$1) -> 7965 | H34: 85 | I34: 0 | J34: 1 | K34: 0 | L34: 0 | M34: 30 | N34: =IF((H34+I34)>0,N$1/100*(H34+I34),0) -> 5.95 | O34: =IF((H34+I34)>0,O$1*(H34+I34),0) -> 0.14166667 | P34: =IF((H34+I34)>0,P$1*(H34+I34),0) -> 0.017 | R34: =VLOOKUP(R$2,'Materia prima'!$B:$J,2,0)*H34 -> 663.85 | S34: =VLOOKUP(S$2,'Materia prima'!$B:$J,2,0)*I34 -> 0 | T34: =VLOOKUP(T$2,'Materia prima'!$B:$J,2,0)*J34 -> 100 | U34: =C34*K34 -> 0 | V34: =VLOOKUP(V$2,'Materia prima'!$B:$J,2,0)*L34/1000 -> 0 | W34: =VLOOKUP(W$2,'Materia prima'!$B:$J,2,0)*N34 -> 892.5 | X34: =VLOOKUP(X$2,'Materia prima'!$B:$J,2,0)*O34 -> 24.083333 | Y34: =VLOOKUP(Y$2,'Materia prima'!$B:$J,2,0)*P34 -> 306 | Z34: =VLOOKUP(Z$2,'Materia prima'!$B:$J,2,0)*M34/60 -> 3500 | AA34: =SUM(R34:Y34) -> 1986.4333 | AB34: =SUM(Z34:AA34) -> 5486.4333 | AC34: =CEILING(AB34*$AC$2,100) -> 5900 | AD34: =AC34/AB34 -> 1.0753799 | AF34: =Z34/AB34 -> 0.63793721 | AG34: =$F34/AA34-1 -> 3.0096991 | AH34: =$F34/AB34-1 -> 0.45176283 | AI34: =F34-AA34 -> 5978.5667 | AJ34: =AI34/$F34 -> 0.75060473
E35: =AC35 -> 0 | F35: =+E35*(1+'Materia prima'!$B$1) -> 0 | H35: 0 | I35: 0 | J35: 0 | K35: 0 | L35: 0 | M35: 0 | N35: =IF((H35+I35)>0,N$1/100*(H35+I35),0) -> 0 | O35: =IF((H35+I35)>0,O$1*(H35+I35),0) -> 0 | P35: =IF((H35+I35)>0,P$1*(H35+I35),0) -> 0 | R35: =VLOOKUP(R$2,'Materia prima'!$B:$J,2,0)*H35 -> 0 | S35: =VLOOKUP(S$2,'Materia prima'!$B:$J,2,0)*I35 -> 0 | T35: =VLOOKUP(T$2,'Materia prima'!$B:$J,2,0)*J35 -> 0 | U35: =C35*K35 -> 0 | V35: =VLOOKUP(V$2,'Materia prima'!$B:$J,2,0)*L35/1000 -> 0 | W35: =VLOOKUP(W$2,'Materia prima'!$B:$J,2,0)*N35 -> 0 | X35: =VLOOKUP(X$2,'Materia prima'!$B:$J,2,0)*O35 -> 0 | Y35: =VLOOKUP(Y$2,'Materia prima'!$B:$J,2,0)*P35 -> 0 | Z35: =VLOOKUP(Z$2,'Materia prima'!$B:$J,2,0)*M35/60 -> 0 | AA35: =SUM(R35:Y35) -> 0 | AB35: =SUM(Z35:AA35) -> 0 | AC35: =CEILING(AB35*$AC$2,100) -> 0 | AD35: =AC35/AB35 -> #DIV/0! | AF35: =Z35/AB35 -> #DIV/0! | AG35: =$F35/AA35-1 -> #DIV/0! | AH35: =$F35/AB35-1 -> #DIV/0! | AI35: =F35-AA35 -> 0 | AJ35: =AI35/$F35 -> #DIV/0!
E36: =AC36 -> 0 | F36: =+E36*(1+'Materia prima'!$B$1) -> 0 | H36: 0 | I36: 0 | J36: 0 | K36: 0 | L36: 0 | M36: 0 | N36: =IF((H36+I36)>0,N$1/100*(H36+I36),0) -> 0 | O36: =IF((H36+I36)>0,O$1*(H36+I36),0) -> 0 | P36: =IF((H36+I36)>0,P$1*(H36+I36),0) -> 0 | R36: =VLOOKUP(R$2,'Materia prima'!$B:$J,2,0)*H36 -> 0 | S36: =VLOOKUP(S$2,'Materia prima'!$B:$J,2,0)*I36 -> 0 | T36: =VLOOKUP(T$2,'Materia prima'!$B:$J,2,0)*J36 -> 0 | U36: =C36*K36 -> 0 | V36: =VLOOKUP(V$2,'Materia prima'!$B:$J,2,0)*L36/1000 -> 0 | W36: =VLOOKUP(W$2,'Materia prima'!$B:$J,2,0)*N36 -> 0 | X36: =VLOOKUP(X$2,'Materia prima'!$B:$J,2,0)*O36 -> 0 | Y36: =VLOOKUP(Y$2,'Materia prima'!$B:$J,2,0)*P36 -> 0 | Z36: =VLOOKUP(Z$2,'Materia prima'!$B:$J,2,0)*M36/60 -> 0 | AA36: =SUM(R36:Y36) -> 0 | AB36: =SUM(Z36:AA36) -> 0 | AC36: =CEILING(AB36*$AC$2,100) -> 0 | AD36: =AC36/AB36 -> #DIV/0! | AF36: =Z36/AB36 -> #DIV/0! | AG36: =$F36/AA36-1 -> #DIV/0! | AH36: =$F36/AB36-1 -> #DIV/0! | AI36: =F36-AA36 -> 0 | AJ36: =AI36/$F36 -> #DIV/0!
E37: =AC37 -> 0 | F37: =+E37*(1+'Materia prima'!$B$1) -> 0 | H37: 0 | I37: 0 | J37: 0 | K37: 0 | L37: 0 | M37: 0 | N37: =IF((H37+I37)>0,N$1/100*(H37+I37),0) -> 0 | O37: =IF((H37+I37)>0,O$1*(H37+I37),0) -> 0 | P37: =IF((H37+I37)>0,P$1*(H37+I37),0) -> 0 | R37: =VLOOKUP(R$2,'Materia prima'!$B:$J,2,0)*H37 -> 0 | S37: =VLOOKUP(S$2,'Materia prima'!$B:$J,2,0)*I37 -> 0 | T37: =VLOOKUP(T$2,'Materia prima'!$B:$J,2,0)*J37 -> 0 | U37: =C37*K37 -> 0 | V37: =VLOOKUP(V$2,'Materia prima'!$B:$J,2,0)*L37/1000 -> 0 | W37: =VLOOKUP(W$2,'Materia prima'!$B:$J,2,0)*N37 -> 0 | X37: =VLOOKUP(X$2,'Materia prima'!$B:$J,2,0)*O37 -> 0 | Y37: =VLOOKUP(Y$2,'Materia prima'!$B:$J,2,0)*P37 -> 0 | Z37: =VLOOKUP(Z$2,'Materia prima'!$B:$J,2,0)*M37/60 -> 0 | AA37: =SUM(R37:Y37) -> 0 | AB37: =SUM(Z37:AA37) -> 0 | AC37: =CEILING(AB37*$AC$2,100) -> 0 | AD37: =AC37/AB37 -> #DIV/0! | AF37: =Z37/AB37 -> #DIV/0! | AG37: =$F37/AA37-1 -> #DIV/0! | AH37: =$F37/AB37-1 -> #DIV/0! | AI37: =F37-AA37 -> 0 | AJ37: =AI37/$F37 -> #DIV/0!
E38: =AC38 -> 0 | F38: =+E38*(1+'Materia prima'!$B$1) -> 0 | H38: 0 | I38: 0 | J38: 0 | K38: 0 | L38: 0 | M38: 0 | N38: =IF((H38+I38)>0,N$1/100*(H38+I38),0) -> 0 | O38: =IF((H38+I38)>0,O$1*(H38+I38),0) -> 0 | P38: =IF((H38+I38)>0,P$1*(H38+I38),0) -> 0 | R38: =VLOOKUP(R$2,'Materia prima'!$B:$J,2,0)*H38 -> 0 | S38: =VLOOKUP(S$2,'Materia prima'!$B:$J,2,0)*I38 -> 0 | T38: =VLOOKUP(T$2,'Materia prima'!$B:$J,2,0)*J38 -> 0 | U38: =C38*K38 -> 0 | V38: =VLOOKUP(V$2,'Materia prima'!$B:$J,2,0)*L38/1000 -> 0 | W38: =VLOOKUP(W$2,'Materia prima'!$B:$J,2,0)*N38 -> 0 | X38: =VLOOKUP(X$2,'Materia prima'!$B:$J,2,0)*O38 -> 0 | Y38: =VLOOKUP(Y$2,'Materia prima'!$B:$J,2,0)*P38 -> 0 | Z38: =VLOOKUP(Z$2,'Materia prima'!$B:$J,2,0)*M38/60 -> 0 | AA38: =SUM(R38:Y38) -> 0 | AB38: =SUM(Z38:AA38) -> 0 | AC38: =CEILING(AB38*$AC$2,100) -> 0 | AD38: =AC38/AB38 -> #DIV/0! | AF38: =Z38/AB38 -> #DIV/0! | AG38: =$F38/AA38-1 -> #DIV/0! | AH38: =$F38/AB38-1 -> #DIV/0! | AI38: =F38-AA38 -> 0 | AJ38: =AI38/$F38 -> #DIV/0!
E39: =AC39 -> 0 | F39: =+E39*(1+'Materia prima'!$B$1) -> 0 | H39: 0 | I39: 0 | J39: 0 | K39: 0 | L39: 0 | M39: 0 | N39: =IF((H39+I39)>0,N$1/100*(H39+I39),0) -> 0 | O39: =IF((H39+I39)>0,O$1*(H39+I39),0) -> 0 | P39: =IF((H39+I39)>0,P$1*(H39+I39),0) -> 0 | R39: =VLOOKUP(R$2,'Materia prima'!$B:$J,2,0)*H39 -> 0 | S39: =VLOOKUP(S$2,'Materia prima'!$B:$J,2,0)*I39 -> 0 | T39: =VLOOKUP(T$2,'Materia prima'!$B:$J,2,0)*J39 -> 0 | U39: =C39*K39 -> 0 | V39: =VLOOKUP(V$2,'Materia prima'!$B:$J,2,0)*L39/1000 -> 0 | W39: =VLOOKUP(W$2,'Materia prima'!$B:$J,2,0)*N39 -> 0 | X39: =VLOOKUP(X$2,'Materia prima'!$B:$J,2,0)*O39 -> 0 | Y39: =VLOOKUP(Y$2,'Materia prima'!$B:$J,2,0)*P39 -> 0 | Z39: =VLOOKUP(Z$2,'Materia prima'!$B:$J,2,0)*M39/60 -> 0 | AA39: =SUM(R39:Y39) -> 0 | AB39: =SUM(Z39:AA39) -> 0 | AC39: =CEILING(AB39*$AC$2,100) -> 0 | AD39: =AC39/AB39 -> #DIV/0! | AF39: =Z39/AB39 -> #DIV/0! | AG39: =$F39/AA39-1 -> #DIV/0! | AH39: =$F39/AB39-1 -> #DIV/0! | AI39: =F39-AA39 -> 0 | AJ39: =AI39/$F39 -> #DIV/0!
E40: =AC40 -> 0 | F40: =+E40*(1+'Materia prima'!$B$1) -> 0 | H40: 0 | I40: 0 | J40: 0 | K40: 0 | L40: 0 | M40: 0 | N40: =IF((H40+I40)>0,N$1/100*(H40+I40),0) -> 0 | O40: =IF((H40+I40)>0,O$1*(H40+I40),0) -> 0 | P40: =IF((H40+I40)>0,P$1*(H40+I40),0) -> 0 | R40: =VLOOKUP(R$2,'Materia prima'!$B:$J,2,0)*H40 -> 0 | S40: =VLOOKUP(S$2,'Materia prima'!$B:$J,2,0)*I40 -> 0 | T40: =VLOOKUP(T$2,'Materia prima'!$B:$J,2,0)*J40 -> 0 | U40: =C40*K40 -> 0 | V40: =VLOOKUP(V$2,'Materia prima'!$B:$J,2,0)*L40/1000 -> 0 | W40: =VLOOKUP(W$2,'Materia prima'!$B:$J,2,0)*N40 -> 0 | X40: =VLOOKUP(X$2,'Materia prima'!$B:$J,2,0)*O40 -> 0 | Y40: =VLOOKUP(Y$2,'Materia prima'!$B:$J,2,0)*P40 -> 0 | Z40: =VLOOKUP(Z$2,'Materia prima'!$B:$J,2,0)*M40/60 -> 0 | AA40: =SUM(R40:Y40) -> 0 | AB40: =SUM(Z40:AA40) -> 0 | AC40: =CEILING(AB40*$AC$2,100) -> 0 | AD40: =AC40/AB40 -> #DIV/0! | AF40: =Z40/AB40 -> #DIV/0! | AG40: =$F40/AA40-1 -> #DIV/0! | AH40: =$F40/AB40-1 -> #DIV/0! | AI40: =F40-AA40 -> 0 | AJ40: =AI40/$F40 -> #DIV/0!
E41: =AC41 -> 0 | F41: =+E41*(1+'Materia prima'!$B$1) -> 0 | H41: 0 | I41: 0 | J41: 0 | K41: 0 | L41: 0 | M41: 0 | N41: =IF((H41+I41)>0,N$1/100*(H41+I41),0) -> 0 | O41: =IF((H41+I41)>0,O$1*(H41+I41),0) -> 0 | P41: =IF((H41+I41)>0,P$1*(H41+I41),0) -> 0 | R41: =VLOOKUP(R$2,'Materia prima'!$B:$J,2,0)*H41 -> 0 | S41: =VLOOKUP(S$2,'Materia prima'!$B:$J,2,0)*I41 -> 0 | T41: =VLOOKUP(T$2,'Materia prima'!$B:$J,2,0)*J41 -> 0 | U41: =C41*K41 -> 0 | V41: =VLOOKUP(V$2,'Materia prima'!$B:$J,2,0)*L41/1000 -> 0 | W41: =VLOOKUP(W$2,'Materia prima'!$B:$J,2,0)*N41 -> 0 | X41: =VLOOKUP(X$2,'Materia prima'!$B:$J,2,0)*O41 -> 0 | Y41: =VLOOKUP(Y$2,'Materia prima'!$B:$J,2,0)*P41 -> 0 | Z41: =VLOOKUP(Z$2,'Materia prima'!$B:$J,2,0)*M41/60 -> 0 | AA41: =SUM(R41:Y41) -> 0 | AB41: =SUM(Z41:AA41) -> 0 | AC41: =CEILING(AB41*$AC$2,100) -> 0 | AD41: =AC41/AB41 -> #DIV/0! | AF41: =Z41/AB41 -> #DIV/0! | AG41: =$F41/AA41-1 -> #DIV/0! | AH41: =$F41/AB41-1 -> #DIV/0! | AI41: =F41-AA41 -> 0 | AJ41: =AI41/$F41 -> #DIV/0!
A42: RECIPIENTES | E42: =AC42 -> 0 | F42: =+E42*(1+'Materia prima'!$B$1) -> 0 | H42: 0 | I42: 0 | J42: 0 | K42: 0 | L42: 0 | M42: 0 | N42: =IF((H42+I42)>0,N$1/100*(H42+I42),0) -> 0 | O42: =IF((H42+I42)>0,O$1*(H42+I42),0) -> 0 | P42: =IF((H42+I42)>0,P$1*(H42+I42),0) -> 0 | R42: =VLOOKUP(R$2,'Materia prima'!$B:$J,2,0)*H42 -> 0 | S42: =VLOOKUP(S$2,'Materia prima'!$B:$J,2,0)*I42 -> 0 | T42: =VLOOKUP(T$2,'Materia prima'!$B:$J,2,0)*J42 -> 0 | U42: =C42*K42 -> 0 | V42: =VLOOKUP(V$2,'Materia prima'!$B:$J,2,0)*L42/1000 -> 0 | W42: =VLOOKUP(W$2,'Materia prima'!$B:$J,2,0)*N42 -> 0 | X42: =VLOOKUP(X$2,'Materia prima'!$B:$J,2,0)*O42 -> 0 | Y42: =VLOOKUP(Y$2,'Materia prima'!$B:$J,2,0)*P42 -> 0 | Z42: =VLOOKUP(Z$2,'Materia prima'!$B:$J,2,0)*M42/60 -> 0 | AA42: =SUM(R42:Y42) -> 0 | AB42: =SUM(Z42:AA42) -> 0 | AC42: =CEILING(AB42*$AC$2,100) -> 0 | AD42: =AC42/AB42 -> #DIV/0! | AF42: =Z42/AB42 -> #DIV/0! | AG42: =$F42/AA42-1 -> #DIV/0! | AH42: =$F42/AB42-1 -> #DIV/0! | AI42: =F42-AA42 -> 0 | AJ42: =AI42/$F42 -> #DIV/0!
A43: R1 | B43: Vaso grande vidrio | C43: 1100 | D43: unid. | E43: =AC43 -> 1200 | F43: =+E43*(1+'Materia prima'!$B$1) -> 1620 | H43: 0 | I43: 0 | J43: 0 | K43: 1 | L43: 0 | M43: 0 | N43: =IF((H43+I43)>0,N$1/100*(H43+I43),0) -> 0 | O43: =IF((H43+I43)>0,O$1*(H43+I43),0) -> 0 | P43: =IF((H43+I43)>0,P$1*(H43+I43),0) -> 0 | R43: =VLOOKUP(R$2,'Materia prima'!$B:$J,2,0)*H43 -> 0 | S43: =VLOOKUP(S$2,'Materia prima'!$B:$J,2,0)*I43 -> 0 | T43: =VLOOKUP(T$2,'Materia prima'!$B:$J,2,0)*J43 -> 0 | U43: =C43*K43 -> 1100 | V43: =VLOOKUP(V$2,'Materia prima'!$B:$J,2,0)*L43/1000 -> 0 | W43: =VLOOKUP(W$2,'Materia prima'!$B:$J,2,0)*N43 -> 0 | X43: =VLOOKUP(X$2,'Materia prima'!$B:$J,2,0)*O43 -> 0 | Y43: =VLOOKUP(Y$2,'Materia prima'!$B:$J,2,0)*P43 -> 0 | Z43: =VLOOKUP(Z$2,'Materia prima'!$B:$J,2,0)*M43/60 -> 0 | AA43: =SUM(R43:Y43) -> 1100 | AB43: =SUM(Z43:AA43) -> 1100 | AC43: =CEILING(AB43*$AC$2,100) -> 1200 | AD43: =AC43/AB43 -> 1.0909091 | AF43: =Z43/AB43 -> 0 | AG43: =$F43/AA43-1 -> 0.47272727 | AH43: =$F43/AB43-1 -> 0.47272727 | AI43: =F43-AA43 -> 520 | AJ43: =AI43/$F43 -> 0.32098765
A44: R2 | B44: Vaso Chico vidrio | C44: 1000 | D44: unid. | E44: =AC44 -> 1100 | F44: =+E44*(1+'Materia prima'!$B$1) -> 1485 | H44: 0 | I44: 0 | J44: 0 | K44: 1 | L44: 0 | M44: 0 | N44: =IF((H44+I44)>0,N$1/100*(H44+I44),0) -> 0 | O44: =IF((H44+I44)>0,O$1*(H44+I44),0) -> 0 | P44: =IF((H44+I44)>0,P$1*(H44+I44),0) -> 0 | R44: =VLOOKUP(R$2,'Materia prima'!$B:$J,2,0)*H44 -> 0 | S44: =VLOOKUP(S$2,'Materia prima'!$B:$J,2,0)*I44 -> 0 | T44: =VLOOKUP(T$2,'Materia prima'!$B:$J,2,0)*J44 -> 0 | U44: =C44*K44 -> 1000 | V44: =VLOOKUP(V$2,'Materia prima'!$B:$J,2,0)*L44/1000 -> 0 | W44: =VLOOKUP(W$2,'Materia prima'!$B:$J,2,0)*N44 -> 0 | X44: =VLOOKUP(X$2,'Materia prima'!$B:$J,2,0)*O44 -> 0 | Y44: =VLOOKUP(Y$2,'Materia prima'!$B:$J,2,0)*P44 -> 0 | Z44: =VLOOKUP(Z$2,'Materia prima'!$B:$J,2,0)*M44/60 -> 0 | AA44: =SUM(R44:Y44) -> 1000 | AB44: =SUM(Z44:AA44) -> 1000 | AC44: =CEILING(AB44*$AC$2,100) -> 1100 | AD44: =AC44/AB44 -> 1.1 | AF44: =Z44/AB44 -> 0 | AG44: =$F44/AA44-1 -> 0.485 | AH44: =$F44/AB44-1 -> 0.485 | AI44: =F44-AA44 -> 485 | AJ44: =AI44/$F44 -> 0.32659933
A45: R3 | B45: Portavela vidrio | C45: =6000+4000 -> 10000 | D45: unid. | E45: =AC45 -> 10700 | F45: =+E45*(1+'Materia prima'!$B$1) -> 14445 | H45: 0 | I45: 0 | J45: 0 | K45: 1 | L45: 0 | M45: 0 | N45: =IF((H45+I45)>0,N$1/100*(H45+I45),0) -> 0 | O45: =IF((H45+I45)>0,O$1*(H45+I45),0) -> 0 | P45: =IF((H45+I45)>0,P$1*(H45+I45),0) -> 0 | R45: =VLOOKUP(R$2,'Materia prima'!$B:$J,2,0)*H45 -> 0 | S45: =VLOOKUP(S$2,'Materia prima'!$B:$J,2,0)*I45 -> 0 | T45: =VLOOKUP(T$2,'Materia prima'!$B:$J,2,0)*J45 -> 0 | U45: =C45*K45 -> 10000 | V45: =VLOOKUP(V$2,'Materia prima'!$B:$J,2,0)*L45/1000 -> 0 | W45: =VLOOKUP(W$2,'Materia prima'!$B:$J,2,0)*N45 -> 0 | X45: =VLOOKUP(X$2,'Materia prima'!$B:$J,2,0)*O45 -> 0 | Y45: =VLOOKUP(Y$2,'Materia prima'!$B:$J,2,0)*P45 -> 0 | Z45: =VLOOKUP(Z$2,'Materia prima'!$B:$J,2,0)*M45/60 -> 0 | AA45: =SUM(R45:Y45) -> 10000 | AB45: =SUM(Z45:AA45) -> 10000 | AC45: =CEILING(AB45*$AC$2,100) -> 10700 | AD45: =AC45/AB45 -> 1.07 | AF45: =Z45/AB45 -> 0 | AG45: =$F45/AA45-1 -> 0.4445 | AH45: =$F45/AB45-1 -> 0.4445 | AI45: =F45-AA45 -> 4445 | AJ45: =AI45/$F45 -> 0.30771893
A46: R4 | B46: Cuenco ceramico chico | C46: 2200 | D46: unid. | E46: =AC46 -> 5900 | F46: =+E46*(1+'Materia prima'!$B$1) -> 7965 | H46: 0 | I46: 40 | J46: 1 | K46: 1 | L46: 0 | M46: 20 | N46: =IF((H46+I46)>0,N$1/100*(H46+I46),0) -> 2.8 | O46: =IF((H46+I46)>0,O$1*(H46+I46),0) -> 0.066666667 | P46: =IF((H46+I46)>0,P$1*(H46+I46),0) -> 0.008 | R46: =VLOOKUP(R$2,'Materia prima'!$B:$J,2,0)*H46 -> 0 | S46: =VLOOKUP(S$2,'Materia prima'!$B:$J,2,0)*I46 -> 300 | T46: =VLOOKUP(T$2,'Materia prima'!$B:$J,2,0)*J46 -> 100 | U46: =C46*K46 -> 2200 | V46: =VLOOKUP(V$2,'Materia prima'!$B:$J,2,0)*L46/1000 -> 0 | W46: =VLOOKUP(W$2,'Materia prima'!$B:$J,2,0)*N46 -> 420 | X46: =VLOOKUP(X$2,'Materia prima'!$B:$J,2,0)*O46 -> 11.333333 | Y46: =VLOOKUP(Y$2,'Materia prima'!$B:$J,2,0)*P46 -> 144 | Z46: =VLOOKUP(Z$2,'Materia prima'!$B:$J,2,0)*M46/60 -> 2333.3333 | AA46: =SUM(R46:Y46) -> 3175.3333 | AB46: =SUM(Z46:AA46) -> 5508.6667 | AC46: =CEILING(AB46*$AC$2,100) -> 5900 | AD46: =AC46/AB46 -> 1.0710396 | AF46: =Z46/AB46 -> 0.42357497 | AG46: =$F46/AA46-1 -> 1.5083981 | AH46: =$F46/AB46-1 -> 0.44590342 | AI46: =F46-AA46 -> 4789.6667 | AJ46: =AI46/$F46 -> 0.60133919
A47: R5 | B47: Cuenco ceramico mediano | C47: 2600 | D47: unid. | E47: =AC47 -> 8100 | F47: =+E47*(1+'Materia prima'!$B$1) -> 10935 | H47: 0 | I47: 60 | J47: 1 | K47: 1 | L47: 0 | M47: 30 | N47: =IF((H47+I47)>0,N$1/100*(H47+I47),0) -> 4.2 | O47: =IF((H47+I47)>0,O$1*(H47+I47),0) -> 0.1 | P47: =IF((H47+I47)>0,P$1*(H47+I47),0) -> 0.012 | R47: =VLOOKUP(R$2,'Materia prima'!$B:$J,2,0)*H47 -> 0 | S47: =VLOOKUP(S$2,'Materia prima'!$B:$J,2,0)*I47 -> 450 | T47: =VLOOKUP(T$2,'Materia prima'!$B:$J,2,0)*J47 -> 100 | U47: =C47*K47 -> 2600 | V47: =VLOOKUP(V$2,'Materia prima'!$B:$J,2,0)*L47/1000 -> 0 | W47: =VLOOKUP(W$2,'Materia prima'!$B:$J,2,0)*N47 -> 630 | X47: =VLOOKUP(X$2,'Materia prima'!$B:$J,2,0)*O47 -> 17 | Y47: =VLOOKUP(Y$2,'Materia prima'!$B:$J,2,0)*P47 -> 216 | Z47: =VLOOKUP(Z$2,'Materia prima'!$B:$J,2,0)*M47/60 -> 3500 | AA47: =SUM(R47:Y47) -> 4013 | AB47: =SUM(Z47:AA47) -> 7513 | AC47: =CEILING(AB47*$AC$2,100) -> 8100 | AD47: =AC47/AB47 -> 1.0781312 | AF47: =Z47/AB47 -> 0.46585918 | AG47: =$F47/AA47-1 -> 1.7248941 | AH47: =$F47/AB47-1 -> 0.45547717 | AI47: =F47-AA47 -> 6922 | AJ47: =AI47/$F47 -> 0.63301326
A48: R6 | B48: Cuenco estrella | C48: 4500 | D48: unid. | E48: =AC48 -> 10100 | F48: =+E48*(1+'Materia prima'!$B$1) -> 13635 | H48: 0 | I48: 60 | J48: 1 | K48: 1 | L48: 0 | M48: 30 | N48: =IF((H48+I48)>0,N$1/100*(H48+I48),0) -> 4.2 | O48: =IF((H48+I48)>0,O$1*(H48+I48),0) -> 0.1 | P48: =IF((H48+I48)>0,P$1*(H48+I48),0) -> 0.012 | R48: =VLOOKUP(R$2,'Materia prima'!$B:$J,2,0)*H48 -> 0 | S48: =VLOOKUP(S$2,'Materia prima'!$B:$J,2,0)*I48 -> 450 | T48: =VLOOKUP(T$2,'Materia prima'!$B:$J,2,0)*J48 -> 100 | U48: =C48*K48 -> 4500 | V48: =VLOOKUP(V$2,'Materia prima'!$B:$J,2,0)*L48/1000 -> 0 | W48: =VLOOKUP(W$2,'Materia prima'!$B:$J,2,0)*N48 -> 630 | X48: =VLOOKUP(X$2,'Materia prima'!$B:$J,2,0)*O48 -> 17 | Y48: =VLOOKUP(Y$2,'Materia prima'!$B:$J,2,0)*P48 -> 216 | Z48: =VLOOKUP(Z$2,'Materia prima'!$B:$J,2,0)*M48/60 -> 3500 | AA48: =SUM(R48:Y48) -> 5913 | AB48: =SUM(Z48:AA48) -> 9413 | AC48: =CEILING(AB48*$AC$2,100) -> 10100 | AD48: =AC48/AB48 -> 1.0729842 | AF48: =Z48/AB48 -> 0.3718262 | AG48: =$F48/AA48-1 -> 1.3059361 | AH48: =$F48/AB48-1 -> 0.44852863 | AI48: =F48-AA48 -> 7722 | AJ48: =AI48/$F48 -> 0.56633663
A49: R7 | B49: Bandeja yeso con borde | C49: 1400 | D49: unid. | E49: =AC49 -> 1500 | F49: =+E49*(1+'Materia prima'!$B$1) -> 2025 | H49: 0 | I49: 0 | J49: 0 | K49: 1 | L49: 0 | M49: 0 | N49: =IF((H49+I49)>0,N$1/100*(H49+I49),0) -> 0 | O49: =IF((H49+I49)>0,O$1*(H49+I49),0) -> 0 | P49: =IF((H49+I49)>0,P$1*(H49+I49),0) -> 0 | R49: =VLOOKUP(R$2,'Materia prima'!$B:$J,2,0)*H49 -> 0 | S49: =VLOOKUP(S$2,'Materia prima'!$B:$J,2,0)*I49 -> 0 | T49: =VLOOKUP(T$2,'Materia prima'!$B:$J,2,0)*J49 -> 0 | U49: =C49*K49 -> 1400 | V49: =VLOOKUP(V$2,'Materia prima'!$B:$J,2,0)*L49/1000 -> 0 | W49: =VLOOKUP(W$2,'Materia prima'!$B:$J,2,0)*N49 -> 0 | X49: =VLOOKUP(X$2,'Materia prima'!$B:$J,2,0)*O49 -> 0 | Y49: =VLOOKUP(Y$2,'Materia prima'!$B:$J,2,0)*P49 -> 0 | Z49: =VLOOKUP(Z$2,'Materia prima'!$B:$J,2,0)*M49/60 -> 0 | AA49: =SUM(R49:Y49) -> 1400 | AB49: =SUM(Z49:AA49) -> 1400 | AC49: =CEILING(AB49*$AC$2,100) -> 1500 | AD49: =AC49/AB49 -> 1.0714286 | AF49: =Z49/AB49 -> 0 | AG49: =$F49/AA49-1 -> 0.44642857 | AH49: =$F49/AB49-1 -> 0.44642857 | AI49: =F49-AA49 -> 625 | AJ49: =AI49/$F49 -> 0.30864198
A50: R8 | B50: Alhajero de yeso | C50: 660 | D50: unid. | E50: =AC50 -> 5600 | F50: =+E50*(1+'Materia prima'!$B$1) -> 7560 | H50: 0 | I50: 42 | J50: 1 | K50: 1 | L50: 0 | M50: 30 | N50: =IF((H50+I50)>0,N$1/100*(H50+I50),0) -> 2.94 | O50: =IF((H50+I50)>0,O$1*(H50+I50),0) -> 0.07 | P50: =IF((H50+I50)>0,P$1*(H50+I50),0) -> 0.0084 | R50: =VLOOKUP(R$2,'Materia prima'!$B:$J,2,0)*H50 -> 0 | S50: =VLOOKUP(S$2,'Materia prima'!$B:$J,2,0)*I50 -> 315 | T50: =VLOOKUP(T$2,'Materia prima'!$B:$J,2,0)*J50 -> 100 | U50: =C50*K50 -> 660 | V50: =VLOOKUP(V$2,'Materia prima'!$B:$J,2,0)*L50/1000 -> 0 | W50: =VLOOKUP(W$2,'Materia prima'!$B:$J,2,0)*N50 -> 441 | X50: =VLOOKUP(X$2,'Materia prima'!$B:$J,2,0)*O50 -> 11.9 | Y50: =VLOOKUP(Y$2,'Materia prima'!$B:$J,2,0)*P50 -> 151.2 | Z50: =VLOOKUP(Z$2,'Materia prima'!$B:$J,2,0)*M50/60 -> 3500 | AA50: =SUM(R50:Y50) -> 1679.1 | AB50: =SUM(Z50:AA50) -> 5179.1 | AC50: =CEILING(AB50*$AC$2,100) -> 5600 | AD50: =AC50/AB50 -> 1.0812689 | AF50: =Z50/AB50 -> 0.67579309 | AG50: =$F50/AA50-1 -> 3.502412 | AH50: =$F50/AB50-1 -> 0.45971308 | AI50: =F50-AA50 -> 5880.9 | AJ50: =AI50/$F50 -> 0.77789683
A51: R9 | B51: Piscina de yeso | C51: 1600 | D51: unid. | E51: =AC51 -> 1800 | F51: =+E51*(1+'Materia prima'!$B$1) -> 2430 | H51: 0 | I51: 0 | J51: 0 | K51: 1 | L51: 0 | M51: 0 | N51: =IF((H51+I51)>0,N$1/100*(H51+I51),0) -> 0 | O51: =IF((H51+I51)>0,O$1*(H51+I51),0) -> 0 | P51: =IF((H51+I51)>0,P$1*(H51+I51),0) -> 0 | R51: =VLOOKUP(R$2,'Materia prima'!$B:$J,2,0)*H51 -> 0 | S51: =VLOOKUP(S$2,'Materia prima'!$B:$J,2,0)*I51 -> 0 | T51: =VLOOKUP(T$2,'Materia prima'!$B:$J,2,0)*J51 -> 0 | U51: =C51*K51 -> 1600 | V51: =VLOOKUP(V$2,'Materia prima'!$B:$J,2,0)*L51/1000 -> 0 | W51: =VLOOKUP(W$2,'Materia prima'!$B:$J,2,0)*N51 -> 0 | X51: =VLOOKUP(X$2,'Materia prima'!$B:$J,2,0)*O51 -> 0 | Y51: =VLOOKUP(Y$2,'Materia prima'!$B:$J,2,0)*P51 -> 0 | Z51: =VLOOKUP(Z$2,'Materia prima'!$B:$J,2,0)*M51/60 -> 0 | AA51: =SUM(R51:Y51) -> 1600 | AB51: =SUM(Z51:AA51) -> 1600 | AC51: =CEILING(AB51*$AC$2,100) -> 1800 | AD51: =AC51/AB51 -> 1.125 | AF51: =Z51/AB51 -> 0 | AG51: =$F51/AA51-1 -> 0.51875 | AH51: =$F51/AB51-1 -> 0.51875 | AI51: =F51-AA51 -> 830 | AJ51: =AI51/$F51 -> 0.34156379
A52: R10 | B52: Vaso grande labrado | C52: 1600 | D52: unid. | E52: =AC52 -> 8200 | F52: =+E52*(1+'Materia prima'!$B$1) -> 11070 | H52: 0 | I52: 110 | J52: 1 | K52: 1 | L52: 0 | M52: 30 | N52: =IF((H52+I52)>0,N$1/100*(H52+I52),0) -> 7.7 | O52: =IF((H52+I52)>0,O$1*(H52+I52),0) -> 0.18333333 | P52: =IF((H52+I52)>0,P$1*(H52+I52),0) -> 0.022 | R52: =VLOOKUP(R$2,'Materia prima'!$B:$J,2,0)*H52 -> 0 | S52: =VLOOKUP(S$2,'Materia prima'!$B:$J,2,0)*I52 -> 825 | T52: =VLOOKUP(T$2,'Materia prima'!$B:$J,2,0)*J52 -> 100 | U52: =C52*K52 -> 1600 | V52: =VLOOKUP(V$2,'Materia prima'!$B:$J,2,0)*L52/1000 -> 0 | W52: =VLOOKUP(W$2,'Materia prima'!$B:$J,2,0)*N52 -> 1155 | X52: =VLOOKUP(X$2,'Materia prima'!$B:$J,2,0)*O52 -> 31.166667 | Y52: =VLOOKUP(Y$2,'Materia prima'!$B:$J,2,0)*P52 -> 396 | Z52: =VLOOKUP(Z$2,'Materia prima'!$B:$J,2,0)*M52/60 -> 3500 | AA52: =SUM(R52:Y52) -> 4107.1667 | AB52: =SUM(Z52:AA52) -> 7607.1667 | AC52: =CEILING(AB52*$AC$2,100) -> 8200 | AD52: =AC52/AB52 -> 1.0779309 | AF52: =Z52/AB52 -> 0.46009246 | AG52: =$F52/AA52-1 -> 1.6952887 | AH52: =$F52/AB52-1 -> 0.45520671 | AI52: =F52-AA52 -> 6962.8333 | AJ52: =AI52/$F52 -> 0.62898223
A53: R11 | B53: Vaso Chico vela | C53: 1400 | D53: unid. | E53: =AC53 -> 6100 | F53: =+E53*(1+'Materia prima'!$B$1) -> 8235 | H53: 0 | I53: 55 | J53: 1 | K53: 1 | L53: 0 | M53: 25 | N53: =IF((H53+I53)>0,N$1/100*(H53+I53),0) -> 3.85 | O53: =IF((H53+I53)>0,O$1*(H53+I53),0) -> 0.091666667 | P53: =IF((H53+I53)>0,P$1*(H53+I53),0) -> 0.011 | R53: =VLOOKUP(R$2,'Materia prima'!$B:$J,2,0)*H53 -> 0 | S53: =VLOOKUP(S$2,'Materia prima'!$B:$J,2,0)*I53 -> 412.5 | T53: =VLOOKUP(T$2,'Materia prima'!$B:$J,2,0)*J53 -> 100 | U53: =C53*K53 -> 1400 | V53: =VLOOKUP(V$2,'Materia prima'!$B:$J,2,0)*L53/1000 -> 0 | W53: =VLOOKUP(W$2,'Materia prima'!$B:$J,2,0)*N53 -> 577.5 | X53: =VLOOKUP(X$2,'Materia prima'!$B:$J,2,0)*O53 -> 15.583333 | Y53: =VLOOKUP(Y$2,'Materia prima'!$B:$J,2,0)*P53 -> 198 | Z53: =VLOOKUP(Z$2,'Materia prima'!$B:$J,2,0)*M53/60 -> 2916.6667 | AA53: =SUM(R53:Y53) -> 2703.5833 | AB53: =SUM(Z53:AA53) -> 5620.25 | AC53: =CEILING(AB53*$AC$2,100) -> 6100 | AD53: =AC53/AB53 -> 1.085361 | AF53: =Z53/AB53 -> 0.51895675 | AG53: =$F53/AA53-1 -> 2.0459575 | AH53: =$F53/AB53-1 -> 0.46523731 | AI53: =F53-AA53 -> 5531.4167 | AJ53: =AI53/$F53 -> 0.67169601
A54: R12 | B54: Bandeja oval grande | E54: =AC54 -> 4200 | F54: =+E54*(1+'Materia prima'!$B$1) -> 5670 | H54: 0 | I54: 0 | J54: 0 | K54: 0 | L54: 250 | M54: 30 | N54: =IF((H54+I54)>0,N$1/100*(H54+I54),0) -> 0 | O54: =IF((H54+I54)>0,O$1*(H54+I54),0) -> 0 | P54: =IF((H54+I54)>0,P$1*(H54+I54),0) -> 0 | R54: =VLOOKUP(R$2,'Materia prima'!$B:$J,2,0)*H54 -> 0 | S54: =VLOOKUP(S$2,'Materia prima'!$B:$J,2,0)*I54 -> 0 | T54: =VLOOKUP(T$2,'Materia prima'!$B:$J,2,0)*J54 -> 0 | U54: =C54*K54 -> 0 | V54: =VLOOKUP(V$2,'Materia prima'!$B:$J,2,0)*L54/1000 -> 337.5 | W54: =VLOOKUP(W$2,'Materia prima'!$B:$J,2,0)*N54 -> 0 | X54: =VLOOKUP(X$2,'Materia prima'!$B:$J,2,0)*O54 -> 0 | Y54: =VLOOKUP(Y$2,'Materia prima'!$B:$J,2,0)*P54 -> 0 | Z54: =VLOOKUP(Z$2,'Materia prima'!$B:$J,2,0)*M54/60 -> 3500 | AA54: =SUM(R54:Y54) -> 337.5 | AB54: =SUM(Z54:AA54) -> 3837.5 | AC54: =CEILING(AB54*$AC$2,100) -> 4200 | AD54: =AC54/AB54 -> 1.0944625 | AF54: =Z54/AB54 -> 0.91205212 | AG54: =$F54/AA54-1 -> 15.8 | AH54: =$F54/AB54-1 -> 0.47752443 | AI54: =F54-AA54 -> 5332.5 | AJ54: =AI54/$F54 -> 0.94047619
A55: R13 | B55: Bandeja oval mediana | C55: 1200 | D55: unid. | E55: =AC55 -> 1300 | F55: =+E55*(1+'Materia prima'!$B$1) -> 1755 | H55: 0 | I55: 0 | J55: 0 | K55: 1 | L55: =0*160 -> 0 | M55: =0*30 -> 0 | N55: =IF((H55+I55)>0,N$1/100*(H55+I55),0) -> 0 | O55: =IF((H55+I55)>0,O$1*(H55+I55),0) -> 0 | P55: =IF((H55+I55)>0,P$1*(H55+I55),0) -> 0 | R55: =VLOOKUP(R$2,'Materia prima'!$B:$J,2,0)*H55 -> 0 | S55: =VLOOKUP(S$2,'Materia prima'!$B:$J,2,0)*I55 -> 0 | T55: =VLOOKUP(T$2,'Materia prima'!$B:$J,2,0)*J55 -> 0 | U55: =C55*K55 -> 1200 | V55: =VLOOKUP(V$2,'Materia prima'!$B:$J,2,0)*L55/1000 -> 0 | W55: =VLOOKUP(W$2,'Materia prima'!$B:$J,2,0)*N55 -> 0 | X55: =VLOOKUP(X$2,'Materia prima'!$B:$J,2,0)*O55 -> 0 | Y55: =VLOOKUP(Y$2,'Materia prima'!$B:$J,2,0)*P55 -> 0 | Z55: =VLOOKUP(Z$2,'Materia prima'!$B:$J,2,0)*M55/60 -> 0 | AA55: =SUM(R55:Y55) -> 1200 | AB55: =SUM(Z55:AA55) -> 1200 | AC55: =CEILING(AB55*$AC$2,100) -> 1300 | AD55: =AC55/AB55 -> 1.0833333 | AF55: =Z55/AB55 -> 0 | AG55: =$F55/AA55-1 -> 0.4625 | AH55: =$F55/AB55-1 -> 0.4625 | AI55: =F55-AA55 -> 555 | AJ55: =AI55/$F55 -> 0.31623932
A56: R14 | B56: Tapa Alhajero | C56: 200 | D56: unid. | E56: =AC56 -> 300 | F56: =+E56*(1+'Materia prima'!$B$1) -> 405 | H56: 0 | I56: 0 | J56: 0 | K56: 1 | L56: 0 | M56: 0 | N56: =IF((H56+I56)>0,N$1/100*(H56+I56),0) -> 0 | O56: =IF((H56+I56)>0,O$1*(H56+I56),0) -> 0 | P56: =IF((H56+I56)>0,P$1*(H56+I56),0) -> 0 | R56: =VLOOKUP(R$2,'Materia prima'!$B:$J,2,0)*H56 -> 0 | S56: =VLOOKUP(S$2,'Materia prima'!$B:$J,2,0)*I56 -> 0 | T56: =VLOOKUP(T$2,'Materia prima'!$B:$J,2,0)*J56 -> 0 | U56: =C56*K56 -> 200 | V56: =VLOOKUP(V$2,'Materia prima'!$B:$J,2,0)*L56/1000 -> 0 | W56: =VLOOKUP(W$2,'Materia prima'!$B:$J,2,0)*N56 -> 0 | X56: =VLOOKUP(X$2,'Materia prima'!$B:$J,2,0)*O56 -> 0 | Y56: =VLOOKUP(Y$2,'Materia prima'!$B:$J,2,0)*P56 -> 0 | Z56: =VLOOKUP(Z$2,'Materia prima'!$B:$J,2,0)*M56/60 -> 0 | AA56: =SUM(R56:Y56) -> 200 | AB56: =SUM(Z56:AA56) -> 200 | AC56: =CEILING(AB56*$AC$2,100) -> 300 | AD56: =AC56/AB56 -> 1.5 | AF56: =Z56/AB56 -> 0 | AG56: =$F56/AA56-1 -> 1.025 | AH56: =$F56/AB56-1 -> 1.025 | AI56: =F56-AA56 -> 205 | AJ56: =AI56/$F56 -> 0.50617284
A57: R15 | B57: Alhajero | C57: 700 | D57: unid. | E57: =AC57 -> 800 | F57: =+E57*(1+'Materia prima'!$B$1) -> 1080 | H57: 0 | I57: 0 | J57: 0 | K57: 1 | L57: 0 | M57: 0 | N57: =IF((H57+I57)>0,N$1/100*(H57+I57),0) -> 0 | O57: =IF((H57+I57)>0,O$1*(H57+I57),0) -> 0 | P57: =IF((H57+I57)>0,P$1*(H57+I57),0) -> 0 | R57: =VLOOKUP(R$2,'Materia prima'!$B:$J,2,0)*H57 -> 0 | S57: =VLOOKUP(S$2,'Materia prima'!$B:$J,2,0)*I57 -> 0 | T57: =VLOOKUP(T$2,'Materia prima'!$B:$J,2,0)*J57 -> 0 | U57: =C57*K57 -> 700 | V57: =VLOOKUP(V$2,'Materia prima'!$B:$J,2,0)*L57/1000 -> 0 | W57: =VLOOKUP(W$2,'Materia prima'!$B:$J,2,0)*N57 -> 0 | X57: =VLOOKUP(X$2,'Materia prima'!$B:$J,2,0)*O57 -> 0 | Y57: =VLOOKUP(Y$2,'Materia prima'!$B:$J,2,0)*P57 -> 0 | Z57: =VLOOKUP(Z$2,'Materia prima'!$B:$J,2,0)*M57/60 -> 0 | AA57: =SUM(R57:Y57) -> 700 | AB57: =SUM(Z57:AA57) -> 700 | AC57: =CEILING(AB57*$AC$2,100) -> 800 | AD57: =AC57/AB57 -> 1.1428571 | AF57: =Z57/AB57 -> 0 | AG57: =$F57/AA57-1 -> 0.54285714 | AH57: =$F57/AB57-1 -> 0.54285714 | AI57: =F57-AA57 -> 380 | AJ57: =AI57/$F57 -> 0.35185185
A58: R16 | B58: Cono | C58: =CEILING(16000/20,10) -> 800 | D58: unid. | E58: =AC58 -> 900 | F58: =+E58*(1+'Materia prima'!$B$1) -> 1215 | H58: 0 | I58: 0 | J58: 0 | K58: 1 | L58: 0 | M58: 0 | N58: =IF((H58+I58)>0,N$1/100*(H58+I58),0) -> 0 | O58: =IF((H58+I58)>0,O$1*(H58+I58),0) -> 0 | P58: =IF((H58+I58)>0,P$1*(H58+I58),0) -> 0 | R58: =VLOOKUP(R$2,'Materia prima'!$B:$J,2,0)*H58 -> 0 | S58: =VLOOKUP(S$2,'Materia prima'!$B:$J,2,0)*I58 -> 0 | T58: =VLOOKUP(T$2,'Materia prima'!$B:$J,2,0)*J58 -> 0 | U58: =C58*K58 -> 800 | V58: =VLOOKUP(V$2,'Materia prima'!$B:$J,2,0)*L58/1000 -> 0 | W58: =VLOOKUP(W$2,'Materia prima'!$B:$J,2,0)*N58 -> 0 | X58: =VLOOKUP(X$2,'Materia prima'!$B:$J,2,0)*O58 -> 0 | Y58: =VLOOKUP(Y$2,'Materia prima'!$B:$J,2,0)*P58 -> 0 | Z58: =VLOOKUP(Z$2,'Materia prima'!$B:$J,2,0)*M58/60 -> 0 | AA58: =SUM(R58:Y58) -> 800 | AB58: =SUM(Z58:AA58) -> 800 | AC58: =CEILING(AB58*$AC$2,100) -> 900 | AD58: =AC58/AB58 -> 1.125 | AF58: =Z58/AB58 -> 0 | AG58: =$F58/AA58-1 -> 0.51875 | AH58: =$F58/AB58-1 -> 0.51875 | AI58: =F58-AA58 -> 415 | AJ58: =AI58/$F58 -> 0.34156379
...

Sheet Combos
A3: 1 | B3: vela aromatica | C3: =E14 -> 7400 | D3: =B4&", "&B5&", "&B6&", "&B7&", "&B8&", "&B9&", "&B10&", "&B11&" y "&B12 -> Angel grande suvenir, Flores decoracion, Dije Cruz Dorada, Bolsa organza 9x12 comunion, , , , y
A4: V27 | B4: =IFERROR(VLOOKUP($A4,Costos!$A:$F,2,0),"")&IFERROR(VLOOKUP($A4,'Materia prima'!$A:$F,2,0),"") -> Angel grande suvenir | C4: =IFERROR(VLOOKUP($A4,Costos!$A:$F,5,0),0)+IFERROR(VLOOKUP($A4,'Materia prima'!$A:$F,5,0),0) -> 4700 | D4: 1 | E4: =IFERROR(C4*D4,0) -> 4700
A5: A1 | B5: =IFERROR(VLOOKUP($A5,Costos!$A:$F,2,0),"")&IFERROR(VLOOKUP($A5,'Materia prima'!$A:$F,2,0),"") -> Flores decoracion | C5: =IFERROR(VLOOKUP($A5,Costos!$A:$F,5,0),0)+IFERROR(VLOOKUP($A5,'Materia prima'!$A:$F,5,0),0) -> 200 | D5: 1 | E5: =IFERROR(C5*D5,0) -> 200
A6: A5 | B6: =IFERROR(VLOOKUP($A6,Costos!$A:$F,2,0),"")&IFERROR(VLOOKUP($A6,'Materia prima'!$A:$F,2,0),"") -> Dije Cruz Dorada | C6: =IFERROR(VLOOKUP($A6,Costos!$A:$F,5,0),0)+IFERROR(VLOOKUP($A6,'Materia prima'!$A:$F,5,0),0) -> 95.588235 | D6: 1 | E6: =IFERROR(C6*D6,0) -> 95.588235
A7: E11 | B7: =IFERROR(VLOOKUP($A7,Costos!$A:$F,2,0),"")&IFERROR(VLOOKUP($A7,'Materia prima'!$A:$F,2,0),"") -> Bolsa organza 9x12 comunion | C7: =IFERROR(VLOOKUP($A7,Costos!$A:$F,5,0),0)+IFERROR(VLOOKUP($A7,'Materia prima'!$A:$F,5,0),0) -> 450 | D7: 1 | E7: =IFERROR(C7*D7,0) -> 450
B8: =IFERROR(VLOOKUP($A8,Costos!$A:$F,2,0),"")&IFERROR(VLOOKUP($A8,'Materia prima'!$A:$F,2,0),"") | C8: =IFERROR(VLOOKUP($A8,Costos!$A:$F,5,0),0)+IFERROR(VLOOKUP($A8,'Materia prima'!$A:$F,5,0),0) -> 0 | D8: 1 | E8: =IFERROR(C8*D8,0) -> 0
B9: =IFERROR(VLOOKUP($A9,Costos!$A:$F,2,0),"")&IFERROR(VLOOKUP($A9,'Materia prima'!$A:$F,2,0),"") | C9: =IFERROR(VLOOKUP($A9,Costos!$A:$F,5,0),0)+IFERROR(VLOOKUP($A9,'Materia prima'!$A:$F,5,0),0) -> 0 | D9: 1 | E9: =IFERROR(C9*D9,0) -> 0
B10: =IFERROR(VLOOKUP($A10,Costos!$A:$F,2,0),"")&IFERROR(VLOOKUP($A10,'Materia prima'!$A:$F,2,0),"") | C10: =IFERROR(VLOOKUP($A10,Costos!$A:$F,5,0),0)+IFERROR(VLOOKUP($A10,'Materia prima'!$A:$F,5,0),0) -> 0 | D10: 1 | E10: =IFERROR(C10*D10,0) -> 0
B11: =IFERROR(VLOOKUP($A11,Costos!$A:$F,2,0),"")&IFERROR(VLOOKUP($A11,'Materia prima'!$A:$F,2,0),"") | C11: =IFERROR(VLOOKUP($A11,Costos!$A:$F,5,0),0)+IFERROR(VLOOKUP($A11,'Materia prima'!$A:$F,5,0),0) -> 0 | D11: 1 | E11: =IFERROR(C11*D11,0) -> 0
B12: =IFERROR(VLOOKUP($A12,Costos!$A:$F,2,0),"")&IFERROR(VLOOKUP($A12,'Materia prima'!$A:$F,2,0),"") | C12: =IFERROR(VLOOKUP($A12,Costos!$A:$F,5,0),0)+IFERROR(VLOOKUP($A12,'Materia prima'!$A:$F,5,0),0) -> 0 | D12: 1 | E12: =IFERROR(C12*D12,0) -> 0
D13: COSTO | E13: =SUM(E4:E12) -> 5445.5882
D14: PRECIO | E14: =CEILING(E13*(1+'Materia prima'!$B$1),100) -> 7400
A16: =MAX(A$2:A15)+1 -> 2 | B16: vela aromatica | C16: =E27 -> 6600 | D16: =B17&", "&B18&", "&B19&", "&B20&", "&B21&", "&B22&", "&B23&", "&B24&" y "&B25 -> Margaritas, Flores decoracion, Cinta, Tarjeta presentacion, Cono, Bolsa celofan 10x20, , y
A17: V3 | B17: =IFERROR(VLOOKUP($A17,Costos!$A:$F,2,0),"")&IFERROR(VLOOKUP($A17,'Materia prima'!$A:$F,2,0),"") -> Margaritas | C17: =IFERROR(VLOOKUP($A17,Costos!$A:$F,5,0),0)+IFERROR(VLOOKUP($A17,'Materia prima'!$A:$F,5,0),0) -> 3000 | D17: 1.1 | E17: =IFERROR(C17*D17,0) -> 3300
A18: A1 | B18: =IFERROR(VLOOKUP($A18,Costos!$A:$F,2,0),"")&IFERROR(VLOOKUP($A18,'Materia prima'!$A:$F,2,0),"") -> Flores decoracion | C18: =IFERROR(VLOOKUP($A18,Costos!$A:$F,5,0),0)+IFERROR(VLOOKUP($A18,'Materia prima'!$A:$F,5,0),0) -> 200 | D18: 1 | E18: =IFERROR(C18*D18,0) -> 200
A19: A3 | B19: =IFERROR(VLOOKUP($A19,Costos!$A:$F,2,0),"")&IFERROR(VLOOKUP($A19,'Materia prima'!$A:$F,2,0),"") -> Cinta | C19: =IFERROR(VLOOKUP($A19,Costos!$A:$F,5,0),0)+IFERROR(VLOOKUP($A19,'Materia prima'!$A:$F,5,0),0) -> 45.9 | D19: 1 | E19: =IFERROR(C19*D19,0) -> 45.9
A20: A4 | B20: =IFERROR(VLOOKUP($A20,Costos!$A:$F,2,0),"")&IFERROR(VLOOKUP($A20,'Materia prima'!$A:$F,2,0),"") -> Tarjeta presentacion | C20: =IFERROR(VLOOKUP($A20,Costos!$A:$F,5,0),0)+IFERROR(VLOOKUP($A20,'Materia prima'!$A:$F,5,0),0) -> 150 | D20: 1.5 | E20: =IFERROR(C20*D20,0) -> 225
A21: R16 | B21: =IFERROR(VLOOKUP($A21,Costos!$A:$F,2,0),"")&IFERROR(VLOOKUP($A21,'Materia prima'!$A:$F,2,0),"") -> Cono | C21: =IFERROR(VLOOKUP($A21,Costos!$A:$F,5,0),0)+IFERROR(VLOOKUP($A21,'Materia prima'!$A:$F,5,0),0) -> 900 | D21: 1 | E21: =IFERROR(C21*D21,0) -> 900
A22: E4 | B22: =IFERROR(VLOOKUP($A22,Costos!$A:$F,2,0),"")&IFERROR(VLOOKUP($A22,'Materia prima'!$A:$F,2,0),"") -> Bolsa celofan 10x20 | C22: =IFERROR(VLOOKUP($A22,Costos!$A:$F,5,0),0)+IFERROR(VLOOKUP($A22,'Materia prima'!$A:$F,5,0),0) -> 180 | D22: 1 | E22: =IFERROR(C22*D22,0) -> 180
B23: =IFERROR(VLOOKUP($A23,Costos!$A:$F,2,0),"")&IFERROR(VLOOKUP($A23,'Materia prima'!$A:$F,2,0),"") | C23: =IFERROR(VLOOKUP($A23,Costos!$A:$F,5,0),0)+IFERROR(VLOOKUP($A23,'Materia prima'!$A:$F,5,0),0) -> 0 | D23: 1 | E23: =IFERROR(C23*D23,0) -> 0
B24: =IFERROR(VLOOKUP($A24,Costos!$A:$F,2,0),"")&IFERROR(VLOOKUP($A24,'Materia prima'!$A:$F,2,0),"") | C24: =IFERROR(VLOOKUP($A24,Costos!$A:$F,5,0),0)+IFERROR(VLOOKUP($A24,'Materia prima'!$A:$F,5,0),0) -> 0 | D24: 1 | E24: =IFERROR(C24*D24,0) -> 0
B25: =IFERROR(VLOOKUP($A25,Costos!$A:$F,2,0),"")&IFERROR(VLOOKUP($A25,'Materia prima'!$A:$F,2,0),"") | C25: =IFERROR(VLOOKUP($A25,Costos!$A:$F,5,0),0)+IFERROR(VLOOKUP($A25,'Materia prima'!$A:$F,5,0),0) -> 0 | D25: 1 | E25: =IFERROR(C25*D25,0) -> 0
D26: COSTO | E26: =SUM(E17:E25) -> 4850.9
D27: PRECIO | E27: =CEILING(E26*(1+'Materia prima'!$B$1),100) -> 6600
